Workbook

Sheet Tracker Field Mapping
A1: Added | B1: SQL MAPPING | C1: Sl No | D1: CTE | F1: Column Name | G1: Description | H1: From System | I1: Front End Field Name | J1: Back End Field Name | K1: Current Status | L1: Comment | M1: Remarks
A2: + | B2: _branch_bu | C2: 1 | D2: pre_calc | F2: BU | G2: value IFS / GDC / UDC / Return | H2: FOCUS | I2: Branch | J2: contact_branch(Shipment Details API) | K2: Available | L2: On COMS user should be able to select Branch while creating shipment.
A3: + | B3: _supplier_name _supplier_code | C3: 2 | D3: pre_calc | F3: Supplier | H3: COMS | I3: Supplier Name | K3: Available | L3: Case 1( PO# line items with Remaining Quantity>0 ) Show the respective Supplier Name of that Line Item. Case 2 (Frieght Order line with Single PO# exists) Show the respective Supplier Name of that shipment. Case 3 (Freight Order line with multiple PO# exists) Show Supplier Name of the PO# which is showing on EKPOREF# column.
A4: + | B4: _po_no_EKPOREF | C4: 3 | D4: pre_calc | F4: EKPOREF# | G4: PO# | H4: COMS | I4: PO # | K4: Available | L4: Case 1( PO# line items with Remaining Quantity>0 ) Show the respective PO# of that Line Item. Case 2 (Frieght Order line with Single PO# exists) Show the respective PO# of that shipment. Case 3 (Freight Order line with multiple PO# exists) Display any one PO# that has the latest CURRENT_PO_PROMISED_DT among all associated PO line items.
A5: + | B5: _secondary_po | C5: 4 | D5: pre_calc | F5: SECONDARY PO | H5: COMS | I5: Show all other PO# seperated by comma except the PO# showing in the EKPOREF# | K5: Available | L5: Case 1 ( PO# line items with Remaining Quantity>0 ) Empty Case 2 (Freight Order line with Single PO# exists) Empty Case 3 (Freight Order line with multiple PO# exists) Display all other PO# values associated with the Freight Order, separated by commas, excluding the PO# shown in the EKPOREF# column.
A6: + | B6: _po_remarks | C6: 5 | D6: pre_calc | F6: PO REMARKS | H6: COMS | I6: PO Remarks | K6: Available | L6: Case 1(PO# line items with Remaining Quantity>0 or Freight Order line with Single PO# exists ) Show the respective PO Remarks of that PO# Line Item. Case 2 (Freight Order line with multiple PO# exists) Display all the remarks associated with the PO line items included in the Freight Order, separated by a " | " delimiter.
A7: + | B7: _commodity | C7: 6 | D7: pre_calc | F7: COMMODITY | H7: COMS | I7: show all different Freight Order Line Item Description | K7: Available | L7: Case 1 ( PO# line items with Remaining Quantity>0 ) show the corresponding PO line item Description. Case 2 (Freight Order line) Display all distinct PO line item descriptions associated with the Freight Order, separated by the "|" symbol.
A8: + | B8: _iss_ref | C8: 7 | D8: pre_calc | F8: ISS REF | H8: COMS | I8: Show the Freight Order No | K8: Available | L8: Case 1 ( PO# line items with Remaining Quantity>0 ) Empty. Case 2 (Freight Order line) Display the Freight Order Number associated with the corresponding shipment.
A9: + | C9: 8 | D9: pre_calc | F9: MODE | H9: FOCUS | I9: Service | J9: service(Shipment Details API) | K9: Available
A10: + | B10: _routed_by | C10: 9 | D10: pre_calc | F10: ROUTED BY | H10: COMS | I10: Routed By | K10: Available
A11: + | B11: _incoterms _incoterms_fo | C11: 10 | D11: pre_calc | F11: INCOTERMS | H11: FOCUS | I11: Shipping Terms | J11: Case 1 ( Freight Order line but shipment not created) Show the value from Inco Terms form Freight Order enrichment table on COMS Case 2 (Freight Order line but Shipment created) shipping_terms(Shipment Details API) | K11: Available | L11: Case 1 ( Freight Order line but shipment not created) Show the value from Inco Terms form Freight Order enrichment table on COMS Case 2 (Freight Order line but Shipment created) shipping_terms(Shipment Details API)
A12: + | B12: _shipment_serial_iss_job | C12: 11 | D12: pre_calc | F12: ISS JOB# | G12: SHIPMENT# | H12: FOCUS | I12: Shipment Serial No | J12: serial_no(Shipment Details API) | K12: Available | L12: Shipment Serial No for the respective Freight Order No
A13: + | B13: _hbl_hawb | C13: 12 | D13: pre_calc | F13: HB/L/HAWB # | G13: HBL#/HAWB# | H13: FOCUS | I13: HB/L Number/HAWB Number | J13: house_no(Shipment Details API) | K13: Available
A14: + | B14: _mbl_mawb | C14: 13 | D14: pre_calc | F14: MBL/MAWB # | G14: MBL#/MAWB# | H14: FOCUS | I14: MB/L Number/MAWB Number | J14: master_no(Shipment Details API) | K14: Available
A15: + | B15: _container_no | C15: 14 | D15: pre_calc | F15: CONTAINER # | G15: Container# | H15: FOCUS | I15: Container Number | J15: equipment_details.*.equipment_no(Shipment Details API) | K15: Available | L15: Show all Container# against the Shipment seperated by Comma
A16: + | B16: _origin_port_pol | C16: 15 | D16: pre_calc | F16: POL | H16: FOCUS | I16: Origin Port/Airport Code | J16: origin_port(Shipment Details API) | K16: Available
A17: + | B17: _origin_port_name | C17: 16 | D17: pre_calc | F17: PORT NAME | H17: FOCUS | I17: Origin Port/Airport Name | J17: to be taken from AVS | K17: Available
A18: + | B18: _origin_country | C18: 17 | D18: pre_calc | F18: ORG COUNTRY | H18: FOCUS | I18: Origin Port/Airport Country Name | J18: to be taken from AVS | K18: Available
A19: + | B19: _origin_region_org_reg | C19: 18 | D19: pre_calc | F19: ORG REGION | H19: FOCUS | I19: Origin Port/Airport Country Region | J19: to be taken from AVS | K19: Available
A20: + | B20: _destination_port_code_dest _destination_port_name_dest _destination_country_code_dest _destination_country_dest _destination_region_reg | C20: 19 | D20: pre_calc | F20: DEST | H20: FOCUS | I20: Destination Port/Airport Code | J20: Name to be taken from AVS+"("+destination_port(Shipment Details API)+")" | K20: Available | L20: show both port code and name
A21: + | B21: _eqpt_type | C21: 20 | D21: pre_calc | F21: EQPT TYPE | H21: FOCUS | I21: Container Type | J21: equipment(Shipment Details API) | K21: Available | L21: Show the value in the format "Total No of Container" * "Container Type".Each container type should be seperated by "+".Say eg: 2 x 20 ft Standard Dry + 1 x 40 ft Standard Dry
A22: + | B22: _20_ft | C22: 21 | D22: pre_calc | F22: 20' | H22: FOCUS | J22: Total Count of 20 ft equipment_details.*.container_type(Shipment Details API) | K22: Available | L22: Show the total No of Containers of 20 feet container type
A23: + | B23: _40_ft | C23: 22 | D23: pre_calc | F23: 40' | H23: FOCUS | J23: Total Count of 40 ft equipment_details.*.container_type(Shipment Details API) | K23: Available | L23: Show the total No of Containers of 40 feet container type
A24: + | B24: _count_of_cont | C24: 23 | D24: pre_calc | F24: # OF CONT. | H24: FOCUS | I24: Show the total No of Containers | J24: Total Count of equipment_details.*.equipment_no(Shipment Details API) | K24: Available | L24: Show the total No of Containers
A25: + | B25: _teus | C25: 24 | D25: pre_calc | F25: # of TEU's | H25: FOCUS | I25: Show the total no of Teus | J25: Calculate total Teus based on equipment_details array(Shipment Details API) | K25: Available | L25: Show the total no of Teus
A26: + | B26: _carrier | C26: 25 | D26: pre_calc | F26: Carrier | H26: FOCUS | I26: Shipping Line/Air Line | J26: Show same like Carrier value showing in AVS | K26: Available | L26: For the Ocean Import take the value from Shipping Line but for Ocean Export take the value from Carrier.Air jobs it will be always Airline.
A27: + | B27: _pr_appr_date | C27: 26 | D27: pre_calc | F27: PR APPR DATE | H27: COMS | I27: REQ_APP_DT | K27: Available | L27: Case 1 ( PO# line items with Remaining Quantity>0 ) Show the REQ_APP_DT of the respective PO Line item. Case 2 (Freight Order line) Display the REQ_APP_DT of the PO number shown in the EKPOREF# column.
A28: + | B28: _po_appr_date | C28: 27 | D28: pre_calc | F28: PO APPR DATE | H28: COMS | I28: PO_APP_DT | K28: Available | L28: Case 1 ( PO# line items with Remaining Quantity>0 ) Show the PO_APP_DT of the respective PO Line item. Case 2 (Freight Order line) Display the PO_APP_DT of the PO number referenced in the EKPOREF# column
A29: + | B29: _po_creation_date | C29: 28 | D29: pre_calc | F29: PO CREATION DATE | G29: PO Created Date | H29: COMS | I29: PO_DATE | K29: Available | L29: Case 1 ( PO# line items with Remaining Quantity>0 ) Show the PO_DATE of the respective PO Line item. Case 2 (Freight Order line) Display the PO_DATE of the PO# shown in the EKPOREF# column
A30: + | B30: _po_recd_date | C30: 29 | D30: pre_calc | F30: PO RECD DATE | G30: PO Received Date | H30: COMS | I30: PO_APP_DT+2 Days | K30: Calculation | L30: Case 1 ( PO# line items with Remaining Quantity>0 ) Show the PO_APP_DT + 2 Days of the respective PO Line item. Case 2 (Freight Order line) Display the value of PO_APP_DT + 2 days for the PO# shown in the EKPOREF# column
A31: + | B31: _po_need_by_date | C31: 30 | D31: pre_calc | F31: PO NEED BY DATE | G31: Current Promise Date | H31: COMS | I31: CURRENT_PO_PROMISED_DT | K31: Available | L31: Case 1 ( PO# line items with Remaining Quantity>0 ) Show the CURRENT_PO_PROMISED_DT of the respective PO Line item. Case 2 (Freight Order line) Display the latest CURRENT_PO_PROMISED_DT from the PO Line Items associated with the PO# shown in the EKPOREF# column.
A32: + | B32: _crd | C32: 31 | D32: pre_calc | F32: CRD | G32: Cargo Readiness Date | H32: FOCUS | I32: Cargo Ready Date Actual | J32: Cargo Ready Date from focus__shipments table | K32: Available
A33: + | B33: _pickup_date | C33: 32 | D33: pre_calc | F33: Pick Up | H33: FOCUS | I33: Pickup/Stuffing Date | J33: pickup_date(Shipment Details API) | K33: Available
A34: + | B34: _cargo_ho | C34: 33 | D34: pre_calc | F34: Cargo H/O | H34: FOCUS | I34: Pickup/Stuffing Date | J34: pickup_date(Shipment Details API) | K34: Available
A35: + | B35: _etd | C35: 34 | D35: pre_calc | F35: ETD | H35: FOCUS | I35: PTD(Wakeo) | J35: etd_wakeo_date(Shipment Details API) | K35: Available
A36: + | B36: _revised_etd | C36: 35 | D36: pre_calc | F36: REVISED ETD | H36: FOCUS | I36: ETD | J36: etd_date(Shipment Details API) | K36: Available
A37: + | B37: _eta | C37: 36 | D37: pre_calc | F37: ETA | H37: FOCUS | I37: PTA(Wakeo) | J37: eta_wakeo_date(Shipment Details API) | K37: Available
A38: + | B38: _revised_eta | C38: 37 | D38: pre_calc | F38: REVISED ETA | H38: FOCUS | I38: ETA | J38: eta_date(Shipment Details API) | K38: Available
A39: + | B39: _do_exp _do_date | C39: 38 | D39: pre_calc | F39: D/O EXP | H39: FOCUS | I39: D/O Expiry Date | J39: ??? | K39: Not Available | M39: New Field needs to create in FOCUS Production environment by Bendetta as "D/O Expiry Date"
A40: + | B40: _del | C40: 39 | D40: pre_calc | F40: DEL | H40: FOCUS | I40: Delivery Date | J40: delivery_date(Shipment Details API) | K40: Available
...

Sheet PBI Param list
A1: column_name
A2: _20_ft
A3: _40_ft
A4: _aux_chrg_aed
A5: _aux_chrg_usd
A6: _arrival_date
A7: _cargo_ho
A8: _crd
A9: _est_cargo_ready_date
A10: _carrier
A11: _cbm
A12: _chargeable_weight
... A84: _teus

Sheet SQL output
A1: SQL cols | B1: Exists? | C1: Needed?
A2: _fo_id | B2: =IFERROR(VLOOKUP(A2,'PBI Param list'!$A$2:$A$84,1,0),"_______OOPS______") -> _______OOPS______ | C2: no
A3: _shipment_serial_iss_job | B3: =IFERROR(VLOOKUP(A3,'PBI Param list'!$A$2:$A$84,1,0),"_______OOPS______") -> _shipment_serial_iss_job | C3: yes
A4: _branch_bu | B4: =IFERROR(VLOOKUP(A4,'PBI Param list'!$A$2:$A$84,1,0),"_______OOPS______") -> _______OOPS______ | C4: yes
A5: _fe_id | B5: =IFERROR(VLOOKUP(A5,'PBI Param list'!$A$2:$A$84,1,0),"_______OOPS______") -> _______OOPS______ | C5: no
A6: _pid | B6: =IFERROR(VLOOKUP(A6,'PBI Param list'!$A$2:$A$84,1,0),"_______OOPS______") -> _pid | C6: yes
A7: _supplier_code | B7: =IFERROR(VLOOKUP(A7,'PBI Param list'!$A$2:$A$84,1,0),"_______OOPS______") -> _supplier_code | C7: yes
A8: _supplier_name | B8: =IFERROR(VLOOKUP(A8,'PBI Param list'!$A$2:$A$84,1,0),"_______OOPS______") -> _supplier_name | C8: yes
A9: _po_no_ekporef | B9: =IFERROR(VLOOKUP(A9,'PBI Param list'!$A$2:$A$84,1,0),"_______OOPS______") -> _po_no_ekporef | C9: yes
A10: _secondary_po | B10: =IFERROR(VLOOKUP(A10,'PBI Param list'!$A$2:$A$84,1,0),"_______OOPS______") -> _secondary_po | C10: yes
A11: _po_remarks | B11: =IFERROR(VLOOKUP(A11,'PBI Param list'!$A$2:$A$84,1,0),"_______OOPS______") -> _po_remarks | C11: yes
A12: _commodity | B12: =IFERROR(VLOOKUP(A12,'PBI Param list'!$A$2:$A$84,1,0),"_______OOPS______") -> _commodity | C12: yes
A13: _iss_ref | B13: =IFERROR(VLOOKUP(A13,'PBI Param list'!$A$2:$A$84,1,0),"_______OOPS______") -> _iss_ref | C13: yes
... A121: _row_type | B121: =IFERROR(VLOOKUP(A121,'PBI Param list'!$A$2:$A$84,1,0),"_______OOPS______") -> _row_type | C121: no
