Workbook

Sheet Tracker
A1: S. NO. | B1: BU | C1: Supplier | D1: EKPOREF# | E1: SECONDARY PO | F1: PO REMARKS | G1: COMMODITY | H1: ISS REF | I1: MODE | J1: ROUTED BY | K1: INCOTERMS | L1: ISS JOB# | M1: HB/L/HAWB # | N1: MBL/MAWB # | O1: CONTAINER # | P1: POL | Q1: PORT NAME | R1: ORG COUNTRY | S1: ORG REGION | T1: DEST | U1: EQPT TYPE | V1: 20' | W1: 40' | X1: # OF CONT. | Y1: # of TEU's | Z1: Carrier | AA1: PR APPR DATE | AB1: PO APPR DATE | AC1: PO CREATION DATE | AD1: PO RECD DATE | AE1: PO NEED BY DATE | AF1: CRD | AG1: Pick Up | AH1: Cargo H/O | AI1: ETD | AJ1: REVISED ETD | AK1: ETA | AL1: REVISED ETA | AM1: D/O EXP | AN1: DEL | AO1: STATUS | AP1: DELIVERY LOCATION | AQ1: INNER QTY | AR1: CBM | AS1: G/W (KGS.) | AT1: C/W (KGS.) | AU1: QTY | AV1: PACK TYPE | AW1: Invoice (AED) | AX1: SHIPMENT REMARKS/UPDATES | AY1: P/A Sent | AZ1: D/N | BA1: ON TIME ORDER PLACEMENT PERF % | BB1: Supplier committed product readiness performance % | BC1: ISS container booking performance % | BD1: ISS Transit Lead Time Perf % | BE1: ISS custom clearance Perf % | BF1: E2E TOTAL LEAD TIME ACCURACY | BG1: No of Days Total Comm LT (as per contract) | BH1: Actual Lead (PO to Date) | BI1: HEALTH CHECK | BJ1: REASON CODE | BK1: No of Days Order Placement LT | BL1: No of Days Supplier Production Lead Time | BM1: No of Days Custom Clearance LT | BN1: No of Days ISS Cont Booking LT | BO1: No of Days Transit LT | BP1: E2E Total LT | BQ1: ORG CHARGES (USD) | BR1: FRT CHGS (USD) | BS1: DEST CHARGES (USD) | BT1: Ancillary Charges (AED) | BU1: Ancillary Charge Type | BV1: ORG CHGS (AED) | BW1: FRT CHGS (AED) | BX1: DEST CHGS (AED) | BY1: P2P VALUE | BZ1: TOTAL CHARGES (AED) | CA1: REQUISITION / BILLING NOTES | CB1: PR # | CC1: PR DATE | CD1: REQ STATUS | CE1: SPO # | CF1: PO STATUS | CG1: SPO /Inv Val(AED) | CH1: Sent to OPS | CI1: Invoice # | CJ1: Billing Status | CK1: Billing Month | CL1: GRN | CM1: GRN STATUS | CN1: PAYMENT STATUS | CO1: ADDL PO | CP1: ADDL INV CHGS | CQ1: ADDL INV # | CR1: ADDL PO GRN # | CS1: ADDL INV BILLING MONTH | CT1: ADDL INV PAYMENT STATUS | CU1: Days Delayed - ETD | CV1: Days Delayed - ETA | CW1: RDD-ETA | CX1: Invoice ( USD) | CY1: NBD TO CRD | CZ1: PO TO CRD (Supplier Response) | DA1: CRD TO ETD | DB1: ETD TO ETA | DC1: ETA TO DEL | DD1: NBD TO ETA | DE1: NBD TO DEL | DF1: AVERAGE LT | DG1: BILLING REPORT | DH1: Ancilliary Charge Form No
C2: IACOBUCCI HF AEROSPACE S.P.A. | D2: 422007642-18 | F2: Revised PO to add extra quantity | G2: STEAM SPOUT | AA2: 45939 | AB2: 45944 | AC2: 45945 | AD2: 45946 | AE2: 46019 | AO2: Pending | AQ2: 43200 | BA2: =IF(Table1[[#This Row],[PO APPR DATE]]>0,IF(Table1[[#This Row],[PO APPR DATE]]-Table1[[#This Row],[PR APPR DATE]]<=5,1,1-ABS(Table1[[#This Row],[PO APPR DATE]]-Table1[[#This Row],[PR APPR DATE]])/5),0) -> 1 | BB2: {=IFERROR(_xlfn.IFS(ISBLANK(Table1[[#This Row],[PO APPR DATE]]),0,Table1[[#This Row],[CRD]]="",0,Table1[[#This Row],[CRD]]-Table1[[#This Row],[PO APPR DATE]]<=VLOOKUP(Table1[[#This Row],[Supplier ]],SupplierLeadTimeMaster!$A$2:$B$235,2,0),1,(Table1[[#This Row],[CRD]]-Table1[[#This Row],[PO APPR DATE]])>VLOOKUP(Table1[[#This Row],[Supplier ]],SupplierLeadTimeMaster!$A$2:$B$235,2,0),1-ABS(Table1[[#This Row],[CRD]]-Table1[[#This Row],[PO APPR DATE]])/VLOOKUP(Table1[[#This Row],[Supplier ]],SupplierLeadTimeMaster!$A$2:$B$235,2,0)),"")} -> 0 | BC2: =IFERROR(IF(AND(Table1[[#This Row],[ETD]]>0,Table1[[#This Row],[No of Days ISS Cont Booking LT]]>0),IF((Table1[[#This Row],[ETD]]-Table1[[#This Row],[CRD]])<=7,1,1-ABS(Table1[[#This Row],[ETD]]-Table1[[#This Row],[CRD]])/7),0),"") -> 0 | BD2: {=_xlfn.IFS(Table1[[#This Row],[DEL]]="",0,Table1[[#This Row],[ORG COUNTRY]]="",0,ISBLANK(Table1[[#This Row],[ETD]]),0,Table1[[#This Row],[ETA]]="",0,Table1[[#This Row],[ETA]]-Table1[[#This Row],[ETD]]<=VLOOKUP(Table1[[#This Row],[ORG COUNTRY]],CountryTransitTimeMaster!$B$2:$C$44,2,FALSE),1,Table1[[#This Row],[ETA]]-Table1[[#This Row],[ETD]]>VLOOKUP(Table1[[#This Row],[ORG COUNTRY]],CountryTransitTimeMaster!$B$2:$C$44,2,FALSE),1-ABS(Table1[[#This Row],[ETA]]-Table1[[#This Row],[ETD]])/VLOOKUP(Table1[[#This Row],[ORG COUNTRY]],CountryTransitTimeMaster!$B$2:$C$44,2,FALSE))} -> 0 | BE2: {=_xlfn.IFS(Table1[[#This Row],[DEL]]="",0,ISBLANK(Table1[[#This Row],[DEL]]),0,Table1[[#This Row],[DEL]]-Table1[[#This Row],[ETA]]<=3,1,(Table1[[#This Row],[DEL]]-Table1[[#This Row],[ETA]])>3,1-ABS(Table1[[#This Row],[DEL]]-Table1[[#This Row],[ETA]])/3)} -> 0 | BF2: =IFERROR(IF(Table1[[#This Row],[E2E Total LT]]>0,1-ABS(Table1[[#This Row],[E2E Total LT]]-Table1[[#This Row],[No of Days Total Comm LT (as per contract)]])/Table1[[#This Row],[No of Days Total Comm LT (as per contract)]],0),"") -> 0 | BG2: {=_xlfn.IFS(Table1[[#This Row],[DEL]]="",0,Table1[[#This Row],[STATUS]]="Cancelled",0,Table1[[#This Row],[ORG COUNTRY]]="",0,ISNONTEXT(Table1[[#This Row],[DEL]]),SUM(VLOOKUP(Table1[[#This Row],[Supplier ]],SupplierLeadTimeMaster!$A$2:$B$235,2,FALSE),VLOOKUP(Table1[[#This Row],[ORG COUNTRY]],CountryTransitTimeMaster!$B$2:$C$44,2,FALSE),7,3,5))} -> 0 | BH2: =IFERROR(IF(SUM(Table1[[#This Row],[No of Days Order Placement LT]],Table1[[#This Row],[No of Days Supplier Production Lead Time]],Table1[[#This Row],[No of Days Custom Clearance LT]],Table1[[#This Row],[No of Days ISS Cont Booking LT]],Table1[[#This Row],[No of Days Transit LT]])>500,0,SUM(Table1[[#This Row],[No of Days Order Placement LT]],Table1[[#This Row],[No of Days Supplier Production Lead Time]],Table1[[#This Row],[No of Days Custom Clearance LT]],Table1[[#This Row],[No of Days ISS Cont Booking LT]],Table1[[#This Row],[No of Days Transit LT]])),0) -> 5 | BI2: {=IFERROR(_xlfn.IFS((Table1[[#This Row],[No of Days Supplier Production Lead Time]])=" "," ",Table1[[#This Row],[Actual Lead (PO to Date)]]-Table1[[#This Row],[No of Days Total Comm LT (as per contract)]]<=15,"Healthy",Table1[[#This Row],[Actual Lead (PO to Date)]]-Table1[[#This Row],[No of Days Total Comm LT (as per contract)]]<=30,"Minor",Table1[[#This Row],[Actual Lead (PO to Date)]]-Table1[[#This Row],[No of Days Total Comm LT (as per contract)]]<=45,"Moderate",Table1[[#This Row],[Actual Lead (PO to Date)]]-Table1[[#This Row],[No of Days Total Comm LT (as per contract)]]<=60,"Major",Table1[[#This Row],[Actual Lead (PO to Date)]]-Table1[[#This Row],[No of Days Total Comm LT (as per contract)]]>60,"Severe",ISBLANK(Table1[[#This Row],[DEL]])," ",ISBLANK(Table1[[#This Row],[ETA]])," ",ISBLANK(Table1[[#This Row],[ETD]])," ",ISBLANK(Table1[[#This Row],[PR APPR DATE]])," ",ISBLANK(Table1[[#This Row],[Actual Lead (PO to Date)]])," ",ISBLANK(Table1[[#This Row],[No of Days Total Comm LT (as per contract)]])," ")," ")} -> Healthy | BJ2: {=IFERROR(_xlfn.IFS(Table1[[#This Row],[HEALTH CHECK]]=" ","",Table1[[#This Row],[HEALTH CHECK]]="Healthy"," ",Table1[[#This Row],[ON TIME ORDER PLACEMENT PERF %]]<100%,"PR to PO Delay",Table1[[#This Row],[Supplier committed product readiness performance % ]]<100%,"Product Readiness Delay",Table1[[#This Row],[ISS container booking performance %]]<100%,"Booking Delay",Table1[[#This Row],[ISS Transit Lead Time Perf %]]<100%,"Trans Shipment Delay",Table1[[#This Row],[ISS custom clearance Perf % ]]<100%,"Custom Clearance Delay")," ")} | BK2: {=_xlfn.IFS(ISBLANK(Table1[[#This Row],[PR APPR DATE]]),0,ISBLANK(Table1[[#This Row],[PO APPR DATE]]),0,ISNONTEXT(Table1[[#This Row],[PO APPR DATE]]),Table1[[#This Row],[PO APPR DATE]]-Table1[[#This Row],[PR APPR DATE]])} -> 5 | BL2: {=_xlfn.IFS((Table1[[#This Row],[DEL]])="",0,ISBLANK(Table1[[#This Row],[CRD]]),0,ISBLANK(Table1[[#This Row],[PO APPR DATE]]),0,ISNONTEXT(Table1[[#This Row],[PO APPR DATE]]),Table1[[#This Row],[CRD]]-Table1[[#This Row],[PO APPR DATE]])} -> 0 | BM2: =IFERROR(IF(Table1[[#This Row],[DEL]]>0,Table1[[#This Row],[DEL]]-Table1[[#This Row],[ETA]],0),0) -> 0 | BN2: =IFERROR(IF(Table1[[#This Row],[ETD]]>0,(Table1[[#This Row],[ETD]]-Table1[[#This Row],[CRD]]),0),"") -> 0 | BO2: =IFERROR(IF(Table1[[#This Row],[ETA]]>0,(Table1[[#This Row],[ETA]]-Table1[[#This Row],[ETD]]),0),0) -> 0 | BP2: {=_xlfn.IFS(Table1[[#This Row],[DEL]]="",0,Table1[[#This Row],[DEL]]="",0,ISBLANK(Table1[[#This Row],[PR APPR DATE]]),0,ISBLANK(Table1[[#This Row],[DEL]]),0,ISNONTEXT(Table1[[#This Row],[PR APPR DATE]]),Table1[[#This Row],[DEL]]-Table1[[#This Row],[PR APPR DATE]],Table1[[#This Row],[DEL]]="",0)} -> 0 | BQ2: =Table1[[#This Row],[ORG CHGS (AED)]]/3.673 -> 0 | BR2: =Table1[[#This Row],[FRT CHGS (AED)]]/3.673 -> 0 | BS2: =Table1[[#This Row],[DEST CHGS (AED)]]/3.673 -> 0 | BY2: =SUM(Table1[[#This Row],[ORG CHGS (AED)]],Table1[[#This Row],[FRT CHGS (AED)]],Table1[[#This Row],[DEST CHGS (AED)]]) -> 0 | BZ2: =SUM(Table1[[#This Row],[P2P VALUE]]+Table1[[#This Row],[Ancillary Charges (AED)]]) -> 0 | CD2: =IF(ISBLANK(Table1[[#This Row],[PR DATE]]),"Pending","Logged") -> Pending | CF2: =IF(ISBLANK(Table1[[#This Row],[SPO '#]]),"Pending","Received") -> Pending | CJ2: {=_xlfn.IFS(ISTEXT(Table1[[#This Row],[Invoice '#]]),"Billed",Table1[[#This Row],[PO STATUS]]="Received","Pending",Table1[[#This Row],[PO STATUS]]="Pending","Pending")} -> Pending | CM2: =IF(ISBLANK(Table1[[#This Row],[GRN]]),"Pending","Complete") -> Pending | CU2: =IF(Table1[[#This Row],[DEL]]="","",Table1[[#This Row],[REVISED ETD]]-Table1[[#This Row],[ETD]]) | CV2: =IF(Table1[[#This Row],[DEL]]="","",Table1[[#This Row],[REVISED ETA]]-Table1[[#This Row],[ETA]]) | CW2: =IF(Table1[[#This Row],[DEL]]="","",Table1[[#This Row],[ETA]]-Table1[[#This Row],[PO NEED BY DATE]]) | CX2: =Table1[[#This Row],[Invoice (AED)]]/3.673 -> 0 | CY2: {=_xlfn.IFS(Table1[[#This Row],[STATUS]]="Cancelled",,Table1[[#This Row],[STATUS]]="Pending",,Table1[[#This Row],[STATUS]]="Not Due",,ISNONTEXT(Table1[[#This Row],[CRD]]),Table1[[#This Row],[CRD]]-Table1[[#This Row],[PO NEED BY DATE]])} -> 0 | CZ2: =IF(Table1[[#This Row],[CRD]]<>"", Table1[[#This Row],[CRD]]-Table1[[#This Row],[PO CREATION DATE]], 0) -> 0 | DA2: =IF(Table1[[#This Row],[REVISED ETD]]<>"", Table1[[#This Row],[REVISED ETD]]-Table1[[#This Row],[CRD]], Table1[[#This Row],[ETD]]-Table1[[#This Row],[CRD]]) -> 0 | DB2: =IF(AND(Table1[[#This Row],[REVISED ETD]]<>"", Table1[[#This Row],[REVISED ETA]]<>""), Table1[[#This Row],[REVISED ETA]]-Table1[[#This Row],[REVISED ETD]], IF(AND(Table1[[#This Row],[REVISED ETA]]<>"", Table1[[#This Row],[REVISED ETD]]=""), Table1[[#This Row],[REVISED ETA]]-Table1[[#This Row],[ETD]], IF(AND(Table1[[#This Row],[REVISED ETA]]="", Table1[[#This Row],[REVISED ETD]]<>""), Table1[[#This Row],[ETA]]-Table1[[#This Row],[REVISED ETD]], IF(AND(Table1[[#This Row],[REVISED ETA]]="", Table1[[#This Row],[REVISED ETD]]=""), Table1[[#This Row],[ETA]]-Table1[[#This Row],[ETD]], "") ) ) ) -> 0 | DC2: =IF(Table1[[#This Row],[REVISED ETA]]<>"", Table1[[#This Row],[DEL]]-Table1[[#This Row],[REVISED ETA]], Table1[[#This Row],[DEL]]-Table1[[#This Row],[ETA]]) -> 0 | DD2: {=_xlfn.IFS(Table1[[#This Row],[STATUS]]="Cancelled",,Table1[[#This Row],[STATUS]]="Pending",,Table1[[#This Row],[STATUS]]="Not Due",,ISNONTEXT(Table1[[#This Row],[ETD]]),Table1[[#This Row],[ETA]]-Table1[[#This Row],[PO NEED BY DATE]])} -> 0 | DE2: =Table1[[#This Row],[PO NEED BY DATE]]-Table1[[#This Row],[DEL]] -> 46019 | DF2: =SUM(Table1[[#This Row],[CRD TO ETD]],Table1[[#This Row],[ETD TO ETA]],Table1[[#This Row],[ETA TO DEL]],Table1[[#This Row],[NBD TO ETA]],Table1[[#This Row],[NBD TO DEL]]) -> 46019
C3: IACOBUCCI HF AEROSPACE S.P.A. | D3: 422007642-17 | F3: PO should be fulfilled | G3: STEAM SPOUT | AA3: 45945 | AB3: 45945 | AC3: 45945 | AD3: 45947 | AE3: 46021 | AO3: Pending | AQ3: 42600 | BA3: =IF(Table1[[#This Row],[PO APPR DATE]]>0,IF(Table1[[#This Row],[PO APPR DATE]]-Table1[[#This Row],[PR APPR DATE]]<=5,1,1-ABS(Table1[[#This Row],[PO APPR DATE]]-Table1[[#This Row],[PR APPR DATE]])/5),0) -> 1 | BB3: {=IFERROR(_xlfn.IFS(ISBLANK(Table1[[#This Row],[PO APPR DATE]]),0,Table1[[#This Row],[CRD]]="",0,Table1[[#This Row],[CRD]]-Table1[[#This Row],[PO APPR DATE]]<=VLOOKUP(Table1[[#This Row],[Supplier ]],SupplierLeadTimeMaster!$A$2:$B$235,2,0),1,(Table1[[#This Row],[CRD]]-Table1[[#This Row],[PO APPR DATE]])>VLOOKUP(Table1[[#This Row],[Supplier ]],SupplierLeadTimeMaster!$A$2:$B$235,2,0),1-ABS(Table1[[#This Row],[CRD]]-Table1[[#This Row],[PO APPR DATE]])/VLOOKUP(Table1[[#This Row],[Supplier ]],SupplierLeadTimeMaster!$A$2:$B$235,2,0)),"")} -> 0 | BC3: =IFERROR(IF(AND(Table1[[#This Row],[ETD]]>0,Table1[[#This Row],[No of Days ISS Cont Booking LT]]>0),IF((Table1[[#This Row],[ETD]]-Table1[[#This Row],[CRD]])<=7,1,1-ABS(Table1[[#This Row],[ETD]]-Table1[[#This Row],[CRD]])/7),0),"") -> 0 | BD3: {=_xlfn.IFS(Table1[[#This Row],[DEL]]="",0,Table1[[#This Row],[ORG COUNTRY]]="",0,ISBLANK(Table1[[#This Row],[ETD]]),0,Table1[[#This Row],[ETA]]="",0,Table1[[#This Row],[ETA]]-Table1[[#This Row],[ETD]]<=VLOOKUP(Table1[[#This Row],[ORG COUNTRY]],CountryTransitTimeMaster!$B$2:$C$44,2,FALSE),1,Table1[[#This Row],[ETA]]-Table1[[#This Row],[ETD]]>VLOOKUP(Table1[[#This Row],[ORG COUNTRY]],CountryTransitTimeMaster!$B$2:$C$44,2,FALSE),1-ABS(Table1[[#This Row],[ETA]]-Table1[[#This Row],[ETD]])/VLOOKUP(Table1[[#This Row],[ORG COUNTRY]],CountryTransitTimeMaster!$B$2:$C$44,2,FALSE))} -> 0 | BE3: {=_xlfn.IFS(Table1[[#This Row],[DEL]]="",0,ISBLANK(Table1[[#This Row],[DEL]]),0,Table1[[#This Row],[DEL]]-Table1[[#This Row],[ETA]]<=3,1,(Table1[[#This Row],[DEL]]-Table1[[#This Row],[ETA]])>3,1-ABS(Table1[[#This Row],[DEL]]-Table1[[#This Row],[ETA]])/3)} -> 0 | BF3: =IFERROR(IF(Table1[[#This Row],[E2E Total LT]]>0,1-ABS(Table1[[#This Row],[E2E Total LT]]-Table1[[#This Row],[No of Days Total Comm LT (as per contract)]])/Table1[[#This Row],[No of Days Total Comm LT (as per contract)]],0),"") -> 0 | BG3: {=_xlfn.IFS(Table1[[#This Row],[DEL]]="",0,Table1[[#This Row],[STATUS]]="Cancelled",0,Table1[[#This Row],[ORG COUNTRY]]="",0,ISNONTEXT(Table1[[#This Row],[DEL]]),SUM(VLOOKUP(Table1[[#This Row],[Supplier ]],SupplierLeadTimeMaster!$A$2:$B$235,2,FALSE),VLOOKUP(Table1[[#This Row],[ORG COUNTRY]],CountryTransitTimeMaster!$B$2:$C$44,2,FALSE),7,3,5))} -> 0 | BH3: =IFERROR(IF(SUM(Table1[[#This Row],[No of Days Order Placement LT]],Table1[[#This Row],[No of Days Supplier Production Lead Time]],Table1[[#This Row],[No of Days Custom Clearance LT]],Table1[[#This Row],[No of Days ISS Cont Booking LT]],Table1[[#This Row],[No of Days Transit LT]])>500,0,SUM(Table1[[#This Row],[No of Days Order Placement LT]],Table1[[#This Row],[No of Days Supplier Production Lead Time]],Table1[[#This Row],[No of Days Custom Clearance LT]],Table1[[#This Row],[No of Days ISS Cont Booking LT]],Table1[[#This Row],[No of Days Transit LT]])),0) -> 0 | BI3: {=IFERROR(_xlfn.IFS((Table1[[#This Row],[No of Days Supplier Production Lead Time]])=" "," ",Table1[[#This Row],[Actual Lead (PO to Date)]]-Table1[[#This Row],[No of Days Total Comm LT (as per contract)]]<=15,"Healthy",Table1[[#This Row],[Actual Lead (PO to Date)]]-Table1[[#This Row],[No of Days Total Comm LT (as per contract)]]<=30,"Minor",Table1[[#This Row],[Actual Lead (PO to Date)]]-Table1[[#This Row],[No of Days Total Comm LT (as per contract)]]<=45,"Moderate",Table1[[#This Row],[Actual Lead (PO to Date)]]-Table1[[#This Row],[No of Days Total Comm LT (as per contract)]]<=60,"Major",Table1[[#This Row],[Actual Lead (PO to Date)]]-Table1[[#This Row],[No of Days Total Comm LT (as per contract)]]>60,"Severe",ISBLANK(Table1[[#This Row],[DEL]])," ",ISBLANK(Table1[[#This Row],[ETA]])," ",ISBLANK(Table1[[#This Row],[ETD]])," ",ISBLANK(Table1[[#This Row],[PR APPR DATE]])," ",ISBLANK(Table1[[#This Row],[Actual Lead (PO to Date)]])," ",ISBLANK(Table1[[#This Row],[No of Days Total Comm LT (as per contract)]])," ")," ")} -> Healthy | BJ3: {=IFERROR(_xlfn.IFS(Table1[[#This Row],[HEALTH CHECK]]=" ","",Table1[[#This Row],[HEALTH CHECK]]="Healthy"," ",Table1[[#This Row],[ON TIME ORDER PLACEMENT PERF %]]<100%,"PR to PO Delay",Table1[[#This Row],[Supplier committed product readiness performance % ]]<100%,"Product Readiness Delay",Table1[[#This Row],[ISS container booking performance %]]<100%,"Booking Delay",Table1[[#This Row],[ISS Transit Lead Time Perf %]]<100%,"Trans Shipment Delay",Table1[[#This Row],[ISS custom clearance Perf % ]]<100%,"Custom Clearance Delay")," ")} | BK3: {=_xlfn.IFS(ISBLANK(Table1[[#This Row],[PR APPR DATE]]),0,ISBLANK(Table1[[#This Row],[PO APPR DATE]]),0,ISNONTEXT(Table1[[#This Row],[PO APPR DATE]]),Table1[[#This Row],[PO APPR DATE]]-Table1[[#This Row],[PR APPR DATE]])} -> 0 | BL3: {=_xlfn.IFS((Table1[[#This Row],[DEL]])="",0,ISBLANK(Table1[[#This Row],[CRD]]),0,ISBLANK(Table1[[#This Row],[PO APPR DATE]]),0,ISNONTEXT(Table1[[#This Row],[PO APPR DATE]]),Table1[[#This Row],[CRD]]-Table1[[#This Row],[PO APPR DATE]])} -> 0 | BM3: =IFERROR(IF(Table1[[#This Row],[DEL]]>0,Table1[[#This Row],[DEL]]-Table1[[#This Row],[ETA]],0),0) -> 0 | BN3: =IFERROR(IF(Table1[[#This Row],[ETD]]>0,(Table1[[#This Row],[ETD]]-Table1[[#This Row],[CRD]]),0),"") -> 0 | BO3: =IFERROR(IF(Table1[[#This Row],[ETA]]>0,(Table1[[#This Row],[ETA]]-Table1[[#This Row],[ETD]]),0),0) -> 0 | BP3: {=_xlfn.IFS(Table1[[#This Row],[DEL]]="",0,Table1[[#This Row],[DEL]]="",0,ISBLANK(Table1[[#This Row],[PR APPR DATE]]),0,ISBLANK(Table1[[#This Row],[DEL]]),0,ISNONTEXT(Table1[[#This Row],[PR APPR DATE]]),Table1[[#This Row],[DEL]]-Table1[[#This Row],[PR APPR DATE]],Table1[[#This Row],[DEL]]="",0)} -> 0 | BQ3: =Table1[[#This Row],[ORG CHGS (AED)]]/3.673 -> 0 | BR3: =Table1[[#This Row],[FRT CHGS (AED)]]/3.673 -> 0 | BS3: =Table1[[#This Row],[DEST CHGS (AED)]]/3.673 -> 0 | BY3: =SUM(Table1[[#This Row],[ORG CHGS (AED)]],Table1[[#This Row],[FRT CHGS (AED)]],Table1[[#This Row],[DEST CHGS (AED)]]) -> 0 | BZ3: =SUM(Table1[[#This Row],[P2P VALUE]]+Table1[[#This Row],[Ancillary Charges (AED)]]) -> 0 | CD3: =IF(ISBLANK(Table1[[#This Row],[PR DATE]]),"Pending","Logged") -> Pending | CF3: =IF(ISBLANK(Table1[[#This Row],[SPO '#]]),"Pending","Received") -> Pending | CJ3: {=_xlfn.IFS(ISTEXT(Table1[[#This Row],[Invoice '#]]),"Billed",Table1[[#This Row],[PO STATUS]]="Received","Pending",Table1[[#This Row],[PO STATUS]]="Pending","Pending")} -> Pending | CM3: =IF(ISBLANK(Table1[[#This Row],[GRN]]),"Pending","Complete") -> Pending | CU3: =IF(Table1[[#This Row],[DEL]]="","",Table1[[#This Row],[REVISED ETD]]-Table1[[#This Row],[ETD]]) | CV3: =IF(Table1[[#This Row],[DEL]]="","",Table1[[#This Row],[REVISED ETA]]-Table1[[#This Row],[ETA]]) | CW3: =IF(Table1[[#This Row],[DEL]]="","",Table1[[#This Row],[ETA]]-Table1[[#This Row],[PO NEED BY DATE]]) | CX3: =Table1[[#This Row],[Invoice (AED)]]/3.673 -> 0 | CY3: {=_xlfn.IFS(Table1[[#This Row],[STATUS]]="Cancelled",,Table1[[#This Row],[STATUS]]="Pending",,Table1[[#This Row],[STATUS]]="Not Due",,ISNONTEXT(Table1[[#This Row],[CRD]]),Table1[[#This Row],[CRD]]-Table1[[#This Row],[PO NEED BY DATE]])} -> 0 | CZ3: =IF(Table1[[#This Row],[CRD]]<>"", Table1[[#This Row],[CRD]]-Table1[[#This Row],[PO CREATION DATE]], 0) -> 0 | DA3: =IF(Table1[[#This Row],[REVISED ETD]]<>"", Table1[[#This Row],[REVISED ETD]]-Table1[[#This Row],[CRD]], Table1[[#This Row],[ETD]]-Table1[[#This Row],[CRD]]) -> 0 | DB3: =IF(AND(Table1[[#This Row],[REVISED ETD]]<>"", Table1[[#This Row],[REVISED ETA]]<>""), Table1[[#This Row],[REVISED ETA]]-Table1[[#This Row],[REVISED ETD]], IF(AND(Table1[[#This Row],[REVISED ETA]]<>"", Table1[[#This Row],[REVISED ETD]]=""), Table1[[#This Row],[REVISED ETA]]-Table1[[#This Row],[ETD]], IF(AND(Table1[[#This Row],[REVISED ETA]]="", Table1[[#This Row],[REVISED ETD]]<>""), Table1[[#This Row],[ETA]]-Table1[[#This Row],[REVISED ETD]], IF(AND(Table1[[#This Row],[REVISED ETA]]="", Table1[[#This Row],[REVISED ETD]]=""), Table1[[#This Row],[ETA]]-Table1[[#This Row],[ETD]], "") ) ) ) -> 0 | DC3: =IF(Table1[[#This Row],[REVISED ETA]]<>"", Table1[[#This Row],[DEL]]-Table1[[#This Row],[REVISED ETA]], Table1[[#This Row],[DEL]]-Table1[[#This Row],[ETA]]) -> 0 | DD3: {=_xlfn.IFS(Table1[[#This Row],[STATUS]]="Cancelled",,Table1[[#This Row],[STATUS]]="Pending",,Table1[[#This Row],[STATUS]]="Not Due",,ISNONTEXT(Table1[[#This Row],[ETD]]),Table1[[#This Row],[ETA]]-Table1[[#This Row],[PO NEED BY DATE]])} -> 0 | DE3: =Table1[[#This Row],[PO NEED BY DATE]]-Table1[[#This Row],[DEL]] -> 46021 | DF3: =SUM(Table1[[#This Row],[CRD TO ETD]],Table1[[#This Row],[ETD TO ETA]],Table1[[#This Row],[ETA TO DEL]],Table1[[#This Row],[NBD TO ETA]],Table1[[#This Row],[NBD TO DEL]]) -> 46021
C4: AL SALEM TRADING ENTERPRISES L.L.C. | D4: 422015518-963 | F4: woven covers po | G4: Non-woven Covers for Headrest, Pillow | AA4: 45945 | AB4: 45945 | AC4: 45945 | AD4: 45947 | AE4: 45948 | AO4: Cancelled | AQ4: 90000 | BA4: =IF(Table1[[#This Row],[PO APPR DATE]]>0,IF(Table1[[#This Row],[PO APPR DATE]]-Table1[[#This Row],[PR APPR DATE]]<=5,1,1-ABS(Table1[[#This Row],[PO APPR DATE]]-Table1[[#This Row],[PR APPR DATE]])/5),0) -> 1 | BB4: {=IFERROR(_xlfn.IFS(ISBLANK(Table1[[#This Row],[PO APPR DATE]]),0,Table1[[#This Row],[CRD]]="",0,Table1[[#This Row],[CRD]]-Table1[[#This Row],[PO APPR DATE]]<=VLOOKUP(Table1[[#This Row],[Supplier ]],SupplierLeadTimeMaster!$A$2:$B$235,2,0),1,(Table1[[#This Row],[CRD]]-Table1[[#This Row],[PO APPR DATE]])>VLOOKUP(Table1[[#This Row],[Supplier ]],SupplierLeadTimeMaster!$A$2:$B$235,2,0),1-ABS(Table1[[#This Row],[CRD]]-Table1[[#This Row],[PO APPR DATE]])/VLOOKUP(Table1[[#This Row],[Supplier ]],SupplierLeadTimeMaster!$A$2:$B$235,2,0)),"")} -> 0 | BC4: =IFERROR(IF(AND(Table1[[#This Row],[ETD]]>0,Table1[[#This Row],[No of Days ISS Cont Booking LT]]>0),IF((Table1[[#This Row],[ETD]]-Table1[[#This Row],[CRD]])<=7,1,1-ABS(Table1[[#This Row],[ETD]]-Table1[[#This Row],[CRD]])/7),0),"") -> 0 | BD4: {=_xlfn.IFS(Table1[[#This Row],[DEL]]="",0,Table1[[#This Row],[ORG COUNTRY]]="",0,ISBLANK(Table1[[#This Row],[ETD]]),0,Table1[[#This Row],[ETA]]="",0,Table1[[#This Row],[ETA]]-Table1[[#This Row],[ETD]]<=VLOOKUP(Table1[[#This Row],[ORG COUNTRY]],CountryTransitTimeMaster!$B$2:$C$44,2,FALSE),1,Table1[[#This Row],[ETA]]-Table1[[#This Row],[ETD]]>VLOOKUP(Table1[[#This Row],[ORG COUNTRY]],CountryTransitTimeMaster!$B$2:$C$44,2,FALSE),1-ABS(Table1[[#This Row],[ETA]]-Table1[[#This Row],[ETD]])/VLOOKUP(Table1[[#This Row],[ORG COUNTRY]],CountryTransitTimeMaster!$B$2:$C$44,2,FALSE))} -> 0 | BE4: {=_xlfn.IFS(Table1[[#This Row],[DEL]]="",0,ISBLANK(Table1[[#This Row],[DEL]]),0,Table1[[#This Row],[DEL]]-Table1[[#This Row],[ETA]]<=3,1,(Table1[[#This Row],[DEL]]-Table1[[#This Row],[ETA]])>3,1-ABS(Table1[[#This Row],[DEL]]-Table1[[#This Row],[ETA]])/3)} -> 0 | BF4: =IFERROR(IF(Table1[[#This Row],[E2E Total LT]]>0,1-ABS(Table1[[#This Row],[E2E Total LT]]-Table1[[#This Row],[No of Days Total Comm LT (as per contract)]])/Table1[[#This Row],[No of Days Total Comm LT (as per contract)]],0),"") -> 0 | BG4: {=_xlfn.IFS(Table1[[#This Row],[DEL]]="",0,Table1[[#This Row],[STATUS]]="Cancelled",0,Table1[[#This Row],[ORG COUNTRY]]="",0,ISNONTEXT(Table1[[#This Row],[DEL]]),SUM(VLOOKUP(Table1[[#This Row],[Supplier ]],SupplierLeadTimeMaster!$A$2:$B$235,2,FALSE),VLOOKUP(Table1[[#This Row],[ORG COUNTRY]],CountryTransitTimeMaster!$B$2:$C$44,2,FALSE),7,3,5))} -> 0 | BH4: =IFERROR(IF(SUM(Table1[[#This Row],[No of Days Order Placement LT]],Table1[[#This Row],[No of Days Supplier Production Lead Time]],Table1[[#This Row],[No of Days Custom Clearance LT]],Table1[[#This Row],[No of Days ISS Cont Booking LT]],Table1[[#This Row],[No of Days Transit LT]])>500,0,SUM(Table1[[#This Row],[No of Days Order Placement LT]],Table1[[#This Row],[No of Days Supplier Production Lead Time]],Table1[[#This Row],[No of Days Custom Clearance LT]],Table1[[#This Row],[No of Days ISS Cont Booking LT]],Table1[[#This Row],[No of Days Transit LT]])),0) -> 0 | BI4: {=IFERROR(_xlfn.IFS((Table1[[#This Row],[No of Days Supplier Production Lead Time]])=" "," ",Table1[[#This Row],[Actual Lead (PO to Date)]]-Table1[[#This Row],[No of Days Total Comm LT (as per contract)]]<=15,"Healthy",Table1[[#This Row],[Actual Lead (PO to Date)]]-Table1[[#This Row],[No of Days Total Comm LT (as per contract)]]<=30,"Minor",Table1[[#This Row],[Actual Lead (PO to Date)]]-Table1[[#This Row],[No of Days Total Comm LT (as per contract)]]<=45,"Moderate",Table1[[#This Row],[Actual Lead (PO to Date)]]-Table1[[#This Row],[No of Days Total Comm LT (as per contract)]]<=60,"Major",Table1[[#This Row],[Actual Lead (PO to Date)]]-Table1[[#This Row],[No of Days Total Comm LT (as per contract)]]>60,"Severe",ISBLANK(Table1[[#This Row],[DEL]])," ",ISBLANK(Table1[[#This Row],[ETA]])," ",ISBLANK(Table1[[#This Row],[ETD]])," ",ISBLANK(Table1[[#This Row],[PR APPR DATE]])," ",ISBLANK(Table1[[#This Row],[Actual Lead (PO to Date)]])," ",ISBLANK(Table1[[#This Row],[No of Days Total Comm LT (as per contract)]])," ")," ")} -> Healthy | BJ4: {=IFERROR(_xlfn.IFS(Table1[[#This Row],[HEALTH CHECK]]=" ","",Table1[[#This Row],[HEALTH CHECK]]="Healthy"," ",Table1[[#This Row],[ON TIME ORDER PLACEMENT PERF %]]<100%,"PR to PO Delay",Table1[[#This Row],[Supplier committed product readiness performance % ]]<100%,"Product Readiness Delay",Table1[[#This Row],[ISS container booking performance %]]<100%,"Booking Delay",Table1[[#This Row],[ISS Transit Lead Time Perf %]]<100%,"Trans Shipment Delay",Table1[[#This Row],[ISS custom clearance Perf % ]]<100%,"Custom Clearance Delay")," ")} | BK4: {=_xlfn.IFS(ISBLANK(Table1[[#This Row],[PR APPR DATE]]),0,ISBLANK(Table1[[#This Row],[PO APPR DATE]]),0,ISNONTEXT(Table1[[#This Row],[PO APPR DATE]]),Table1[[#This Row],[PO APPR DATE]]-Table1[[#This Row],[PR APPR DATE]])} -> 0 | BL4: {=_xlfn.IFS((Table1[[#This Row],[DEL]])="",0,ISBLANK(Table1[[#This Row],[CRD]]),0,ISBLANK(Table1[[#This Row],[PO APPR DATE]]),0,ISNONTEXT(Table1[[#This Row],[PO APPR DATE]]),Table1[[#This Row],[CRD]]-Table1[[#This Row],[PO APPR DATE]])} -> 0 | BM4: =IFERROR(IF(Table1[[#This Row],[DEL]]>0,Table1[[#This Row],[DEL]]-Table1[[#This Row],[ETA]],0),0) -> 0 | BN4: =IFERROR(IF(Table1[[#This Row],[ETD]]>0,(Table1[[#This Row],[ETD]]-Table1[[#This Row],[CRD]]),0),"") -> 0 | BO4: =IFERROR(IF(Table1[[#This Row],[ETA]]>0,(Table1[[#This Row],[ETA]]-Table1[[#This Row],[ETD]]),0),0) -> 0 | BP4: {=_xlfn.IFS(Table1[[#This Row],[DEL]]="",0,Table1[[#This Row],[DEL]]="",0,ISBLANK(Table1[[#This Row],[PR APPR DATE]]),0,ISBLANK(Table1[[#This Row],[DEL]]),0,ISNONTEXT(Table1[[#This Row],[PR APPR DATE]]),Table1[[#This Row],[DEL]]-Table1[[#This Row],[PR APPR DATE]],Table1[[#This Row],[DEL]]="",0)} -> 0 | BQ4: =Table1[[#This Row],[ORG CHGS (AED)]]/3.673 -> 0 | BR4: =Table1[[#This Row],[FRT CHGS (AED)]]/3.673 -> 0 | BS4: =Table1[[#This Row],[DEST CHGS (AED)]]/3.673 -> 0 | BY4: =SUM(Table1[[#This Row],[ORG CHGS (AED)]],Table1[[#This Row],[FRT CHGS (AED)]],Table1[[#This Row],[DEST CHGS (AED)]]) -> 0 | BZ4: =SUM(Table1[[#This Row],[P2P VALUE]]+Table1[[#This Row],[Ancillary Charges (AED)]]) -> 0 | CD4: =IF(ISBLANK(Table1[[#This Row],[PR DATE]]),"Pending","Logged") -> Pending | CF4: =IF(ISBLANK(Table1[[#This Row],[SPO '#]]),"Pending","Received") -> Pending | CJ4: {=_xlfn.IFS(ISTEXT(Table1[[#This Row],[Invoice '#]]),"Billed",Table1[[#This Row],[PO STATUS]]="Received","Pending",Table1[[#This Row],[PO STATUS]]="Pending","Pending")} -> Pending | CM4: =IF(ISBLANK(Table1[[#This Row],[GRN]]),"Pending","Complete") -> Pending | CU4: =IF(Table1[[#This Row],[DEL]]="","",Table1[[#This Row],[REVISED ETD]]-Table1[[#This Row],[ETD]]) | CV4: =IF(Table1[[#This Row],[DEL]]="","",Table1[[#This Row],[REVISED ETA]]-Table1[[#This Row],[ETA]]) | CW4: =IF(Table1[[#This Row],[DEL]]="","",Table1[[#This Row],[ETA]]-Table1[[#This Row],[PO NEED BY DATE]]) | CX4: =Table1[[#This Row],[Invoice (AED)]]/3.673 -> 0 | CY4: {=_xlfn.IFS(Table1[[#This Row],[STATUS]]="Cancelled",,Table1[[#This Row],[STATUS]]="Pending",,Table1[[#This Row],[STATUS]]="Not Due",,ISNONTEXT(Table1[[#This Row],[CRD]]),Table1[[#This Row],[CRD]]-Table1[[#This Row],[PO NEED BY DATE]])} -> 0 | CZ4: =IF(Table1[[#This Row],[CRD]]<>"", Table1[[#This Row],[CRD]]-Table1[[#This Row],[PO CREATION DATE]], 0) -> 0 | DA4: =IF(Table1[[#This Row],[REVISED ETD]]<>"", Table1[[#This Row],[REVISED ETD]]-Table1[[#This Row],[CRD]], Table1[[#This Row],[ETD]]-Table1[[#This Row],[CRD]]) -> 0 | DB4: =IF(AND(Table1[[#This Row],[REVISED ETD]]<>"", Table1[[#This Row],[REVISED ETA]]<>""), Table1[[#This Row],[REVISED ETA]]-Table1[[#This Row],[REVISED ETD]], IF(AND(Table1[[#This Row],[REVISED ETA]]<>"", Table1[[#This Row],[REVISED ETD]]=""), Table1[[#This Row],[REVISED ETA]]-Table1[[#This Row],[ETD]], IF(AND(Table1[[#This Row],[REVISED ETA]]="", Table1[[#This Row],[REVISED ETD]]<>""), Table1[[#This Row],[ETA]]-Table1[[#This Row],[REVISED ETD]], IF(AND(Table1[[#This Row],[REVISED ETA]]="", Table1[[#This Row],[REVISED ETD]]=""), Table1[[#This Row],[ETA]]-Table1[[#This Row],[ETD]], "") ) ) ) -> 0 | DC4: =IF(Table1[[#This Row],[REVISED ETA]]<>"", Table1[[#This Row],[DEL]]-Table1[[#This Row],[REVISED ETA]], Table1[[#This Row],[DEL]]-Table1[[#This Row],[ETA]]) -> 0 | DD4: {=_xlfn.IFS(Table1[[#This Row],[STATUS]]="Cancelled",,Table1[[#This Row],[STATUS]]="Pending",,Table1[[#This Row],[STATUS]]="Not Due",,ISNONTEXT(Table1[[#This Row],[ETD]]),Table1[[#This Row],[ETA]]-Table1[[#This Row],[PO NEED BY DATE]])} -> 0 | DE4: =Table1[[#This Row],[PO NEED BY DATE]]-Table1[[#This Row],[DEL]] -> 45948 | DF4: =SUM(Table1[[#This Row],[CRD TO ETD]],Table1[[#This Row],[ETD TO ETA]],Table1[[#This Row],[ETA TO DEL]],Table1[[#This Row],[NBD TO ETA]],Table1[[#This Row],[NBD TO DEL]]) -> 45948
C5: STEP SOURCING TRADING L.L.C | D5: 422016887-19 | F5: cotton | G5: FC Cotton Coaster | AA5: 45945 | AB5: 45945 | AC5: 45945 | AD5: 45947 | AE5: 46119 | AO5: Not Due | AQ5: 478550 | BA5: =IF(Table1[[#This Row],[PO APPR DATE]]>0,IF(Table1[[#This Row],[PO APPR DATE]]-Table1[[#This Row],[PR APPR DATE]]<=5,1,1-ABS(Table1[[#This Row],[PO APPR DATE]]-Table1[[#This Row],[PR APPR DATE]])/5),0) -> 1 | BB5: {=IFERROR(_xlfn.IFS(ISBLANK(Table1[[#This Row],[PO APPR DATE]]),0,Table1[[#This Row],[CRD]]="",0,Table1[[#This Row],[CRD]]-Table1[[#This Row],[PO APPR DATE]]<=VLOOKUP(Table1[[#This Row],[Supplier ]],SupplierLeadTimeMaster!$A$2:$B$235,2,0),1,(Table1[[#This Row],[CRD]]-Table1[[#This Row],[PO APPR DATE]])>VLOOKUP(Table1[[#This Row],[Supplier ]],SupplierLeadTimeMaster!$A$2:$B$235,2,0),1-ABS(Table1[[#This Row],[CRD]]-Table1[[#This Row],[PO APPR DATE]])/VLOOKUP(Table1[[#This Row],[Supplier ]],SupplierLeadTimeMaster!$A$2:$B$235,2,0)),"")} -> 0 | BC5: =IFERROR(IF(AND(Table1[[#This Row],[ETD]]>0,Table1[[#This Row],[No of Days ISS Cont Booking LT]]>0),IF((Table1[[#This Row],[ETD]]-Table1[[#This Row],[CRD]])<=7,1,1-ABS(Table1[[#This Row],[ETD]]-Table1[[#This Row],[CRD]])/7),0),"") -> 0 | BD5: {=_xlfn.IFS(Table1[[#This Row],[DEL]]="",0,Table1[[#This Row],[ORG COUNTRY]]="",0,ISBLANK(Table1[[#This Row],[ETD]]),0,Table1[[#This Row],[ETA]]="",0,Table1[[#This Row],[ETA]]-Table1[[#This Row],[ETD]]<=VLOOKUP(Table1[[#This Row],[ORG COUNTRY]],CountryTransitTimeMaster!$B$2:$C$44,2,FALSE),1,Table1[[#This Row],[ETA]]-Table1[[#This Row],[ETD]]>VLOOKUP(Table1[[#This Row],[ORG COUNTRY]],CountryTransitTimeMaster!$B$2:$C$44,2,FALSE),1-ABS(Table1[[#This Row],[ETA]]-Table1[[#This Row],[ETD]])/VLOOKUP(Table1[[#This Row],[ORG COUNTRY]],CountryTransitTimeMaster!$B$2:$C$44,2,FALSE))} -> 0 | BE5: {=_xlfn.IFS(Table1[[#This Row],[DEL]]="",0,ISBLANK(Table1[[#This Row],[DEL]]),0,Table1[[#This Row],[DEL]]-Table1[[#This Row],[ETA]]<=3,1,(Table1[[#This Row],[DEL]]-Table1[[#This Row],[ETA]])>3,1-ABS(Table1[[#This Row],[DEL]]-Table1[[#This Row],[ETA]])/3)} -> 0 | BF5: =IFERROR(IF(Table1[[#This Row],[E2E Total LT]]>0,1-ABS(Table1[[#This Row],[E2E Total LT]]-Table1[[#This Row],[No of Days Total Comm LT (as per contract)]])/Table1[[#This Row],[No of Days Total Comm LT (as per contract)]],0),"") -> 0 | BG5: {=_xlfn.IFS(Table1[[#This Row],[DEL]]="",0,Table1[[#This Row],[STATUS]]="Cancelled",0,Table1[[#This Row],[ORG COUNTRY]]="",0,ISNONTEXT(Table1[[#This Row],[DEL]]),SUM(VLOOKUP(Table1[[#This Row],[Supplier ]],SupplierLeadTimeMaster!$A$2:$B$235,2,FALSE),VLOOKUP(Table1[[#This Row],[ORG COUNTRY]],CountryTransitTimeMaster!$B$2:$C$44,2,FALSE),7,3,5))} -> 0 | BH5: =IFERROR(IF(SUM(Table1[[#This Row],[No of Days Order Placement LT]],Table1[[#This Row],[No of Days Supplier Production Lead Time]],Table1[[#This Row],[No of Days Custom Clearance LT]],Table1[[#This Row],[No of Days ISS Cont Booking LT]],Table1[[#This Row],[No of Days Transit LT]])>500,0,SUM(Table1[[#This Row],[No of Days Order Placement LT]],Table1[[#This Row],[No of Days Supplier Production Lead Time]],Table1[[#This Row],[No of Days Custom Clearance LT]],Table1[[#This Row],[No of Days ISS Cont Booking LT]],Table1[[#This Row],[No of Days Transit LT]])),0) -> 0 | BI5: {=IFERROR(_xlfn.IFS((Table1[[#This Row],[No of Days Supplier Production Lead Time]])=" "," ",Table1[[#This Row],[Actual Lead (PO to Date)]]-Table1[[#This Row],[No of Days Total Comm LT (as per contract)]]<=15,"Healthy",Table1[[#This Row],[Actual Lead (PO to Date)]]-Table1[[#This Row],[No of Days Total Comm LT (as per contract)]]<=30,"Minor",Table1[[#This Row],[Actual Lead (PO to Date)]]-Table1[[#This Row],[No of Days Total Comm LT (as per contract)]]<=45,"Moderate",Table1[[#This Row],[Actual Lead (PO to Date)]]-Table1[[#This Row],[No of Days Total Comm LT (as per contract)]]<=60,"Major",Table1[[#This Row],[Actual Lead (PO to Date)]]-Table1[[#This Row],[No of Days Total Comm LT (as per contract)]]>60,"Severe",ISBLANK(Table1[[#This Row],[DEL]])," ",ISBLANK(Table1[[#This Row],[ETA]])," ",ISBLANK(Table1[[#This Row],[ETD]])," ",ISBLANK(Table1[[#This Row],[PR APPR DATE]])," ",ISBLANK(Table1[[#This Row],[Actual Lead (PO to Date)]])," ",ISBLANK(Table1[[#This Row],[No of Days Total Comm LT (as per contract)]])," ")," ")} -> Healthy | BJ5: {=IFERROR(_xlfn.IFS(Table1[[#This Row],[HEALTH CHECK]]=" ","",Table1[[#This Row],[HEALTH CHECK]]="Healthy"," ",Table1[[#This Row],[ON TIME ORDER PLACEMENT PERF %]]<100%,"PR to PO Delay",Table1[[#This Row],[Supplier committed product readiness performance % ]]<100%,"Product Readiness Delay",Table1[[#This Row],[ISS container booking performance %]]<100%,"Booking Delay",Table1[[#This Row],[ISS Transit Lead Time Perf %]]<100%,"Trans Shipment Delay",Table1[[#This Row],[ISS custom clearance Perf % ]]<100%,"Custom Clearance Delay")," ")} | BK5: {=_xlfn.IFS(ISBLANK(Table1[[#This Row],[PR APPR DATE]]),0,ISBLANK(Table1[[#This Row],[PO APPR DATE]]),0,ISNONTEXT(Table1[[#This Row],[PO APPR DATE]]),Table1[[#This Row],[PO APPR DATE]]-Table1[[#This Row],[PR APPR DATE]])} -> 0 | BL5: {=_xlfn.IFS((Table1[[#This Row],[DEL]])="",0,ISBLANK(Table1[[#This Row],[CRD]]),0,ISBLANK(Table1[[#This Row],[PO APPR DATE]]),0,ISNONTEXT(Table1[[#This Row],[PO APPR DATE]]),Table1[[#This Row],[CRD]]-Table1[[#This Row],[PO APPR DATE]])} -> 0 | BM5: =IFERROR(IF(Table1[[#This Row],[DEL]]>0,Table1[[#This Row],[DEL]]-Table1[[#This Row],[ETA]],0),0) -> 0 | BN5: =IFERROR(IF(Table1[[#This Row],[ETD]]>0,(Table1[[#This Row],[ETD]]-Table1[[#This Row],[CRD]]),0),"") -> 0 | BO5: =IFERROR(IF(Table1[[#This Row],[ETA]]>0,(Table1[[#This Row],[ETA]]-Table1[[#This Row],[ETD]]),0),0) -> 0 | BP5: {=_xlfn.IFS(Table1[[#This Row],[DEL]]="",0,Table1[[#This Row],[DEL]]="",0,ISBLANK(Table1[[#This Row],[PR APPR DATE]]),0,ISBLANK(Table1[[#This Row],[DEL]]),0,ISNONTEXT(Table1[[#This Row],[PR APPR DATE]]),Table1[[#This Row],[DEL]]-Table1[[#This Row],[PR APPR DATE]],Table1[[#This Row],[DEL]]="",0)} -> 0 | BQ5: =Table1[[#This Row],[ORG CHGS (AED)]]/3.673 -> 0 | BR5: =Table1[[#This Row],[FRT CHGS (AED)]]/3.673 -> 0 | BS5: =Table1[[#This Row],[DEST CHGS (AED)]]/3.673 -> 0 | BY5: =SUM(Table1[[#This Row],[ORG CHGS (AED)]],Table1[[#This Row],[FRT CHGS (AED)]],Table1[[#This Row],[DEST CHGS (AED)]]) -> 0 | BZ5: =SUM(Table1[[#This Row],[P2P VALUE]]+Table1[[#This Row],[Ancillary Charges (AED)]]) -> 0 | CD5: =IF(ISBLANK(Table1[[#This Row],[PR DATE]]),"Pending","Logged") -> Pending | CF5: =IF(ISBLANK(Table1[[#This Row],[SPO '#]]),"Pending","Received") -> Pending | CJ5: {=_xlfn.IFS(ISTEXT(Table1[[#This Row],[Invoice '#]]),"Billed",Table1[[#This Row],[PO STATUS]]="Received","Pending",Table1[[#This Row],[PO STATUS]]="Pending","Pending")} -> Pending | CM5: =IF(ISBLANK(Table1[[#This Row],[GRN]]),"Pending","Complete") -> Pending | CU5: =IF(Table1[[#This Row],[DEL]]="","",Table1[[#This Row],[REVISED ETD]]-Table1[[#This Row],[ETD]]) | CV5: =IF(Table1[[#This Row],[DEL]]="","",Table1[[#This Row],[REVISED ETA]]-Table1[[#This Row],[ETA]]) | CW5: =IF(Table1[[#This Row],[DEL]]="","",Table1[[#This Row],[ETA]]-Table1[[#This Row],[PO NEED BY DATE]]) | CX5: =Table1[[#This Row],[Invoice (AED)]]/3.673 -> 0 | CY5: {=_xlfn.IFS(Table1[[#This Row],[STATUS]]="Cancelled",,Table1[[#This Row],[STATUS]]="Pending",,Table1[[#This Row],[STATUS]]="Not Due",,ISNONTEXT(Table1[[#This Row],[CRD]]),Table1[[#This Row],[CRD]]-Table1[[#This Row],[PO NEED BY DATE]])} -> 0 | CZ5: =IF(Table1[[#This Row],[CRD]]<>"", Table1[[#This Row],[CRD]]-Table1[[#This Row],[PO CREATION DATE]], 0) -> 0 | DA5: =IF(Table1[[#This Row],[REVISED ETD]]<>"", Table1[[#This Row],[REVISED ETD]]-Table1[[#This Row],[CRD]], Table1[[#This Row],[ETD]]-Table1[[#This Row],[CRD]]) -> 0 | DB5: =IF(AND(Table1[[#This Row],[REVISED ETD]]<>"", Table1[[#This Row],[REVISED ETA]]<>""), Table1[[#This Row],[REVISED ETA]]-Table1[[#This Row],[REVISED ETD]], IF(AND(Table1[[#This Row],[REVISED ETA]]<>"", Table1[[#This Row],[REVISED ETD]]=""), Table1[[#This Row],[REVISED ETA]]-Table1[[#This Row],[ETD]], IF(AND(Table1[[#This Row],[REVISED ETA]]="", Table1[[#This Row],[REVISED ETD]]<>""), Table1[[#This Row],[ETA]]-Table1[[#This Row],[REVISED ETD]], IF(AND(Table1[[#This Row],[REVISED ETA]]="", Table1[[#This Row],[REVISED ETD]]=""), Table1[[#This Row],[ETA]]-Table1[[#This Row],[ETD]], "") ) ) ) -> 0 | DC5: =IF(Table1[[#This Row],[REVISED ETA]]<>"", Table1[[#This Row],[DEL]]-Table1[[#This Row],[REVISED ETA]], Table1[[#This Row],[DEL]]-Table1[[#This Row],[ETA]]) -> 0 | DD5: {=_xlfn.IFS(Table1[[#This Row],[STATUS]]="Cancelled",,Table1[[#This Row],[STATUS]]="Pending",,Table1[[#This Row],[STATUS]]="Not Due",,ISNONTEXT(Table1[[#This Row],[ETD]]),Table1[[#This Row],[ETA]]-Table1[[#This Row],[PO NEED BY DATE]])} -> 0 | DE5: =Table1[[#This Row],[PO NEED BY DATE]]-Table1[[#This Row],[DEL]] -> 46119 | DF5: =SUM(Table1[[#This Row],[CRD TO ETD]],Table1[[#This Row],[ETD TO ETA]],Table1[[#This Row],[ETA TO DEL]],Table1[[#This Row],[NBD TO ETA]],Table1[[#This Row],[NBD TO DEL]]) -> 46119
C6: STEP SOURCING TRADING L.L.C | D6: 422016887-19 | F6: fc cotton | G6: FC Cotton Coaster | AA6: 45945 | AB6: 45945 | AC6: 45945 | AD6: 45947 | AE6: 46057 | AO6: Pending | AQ6: 479000 | BA6: =IF(Table1[[#This Row],[PO APPR DATE]]>0,IF(Table1[[#This Row],[PO APPR DATE]]-Table1[[#This Row],[PR APPR DATE]]<=5,1,1-ABS(Table1[[#This Row],[PO APPR DATE]]-Table1[[#This Row],[PR APPR DATE]])/5),0) -> 1 | BB6: {=IFERROR(_xlfn.IFS(ISBLANK(Table1[[#This Row],[PO APPR DATE]]),0,Table1[[#This Row],[CRD]]="",0,Table1[[#This Row],[CRD]]-Table1[[#This Row],[PO APPR DATE]]<=VLOOKUP(Table1[[#This Row],[Supplier ]],SupplierLeadTimeMaster!$A$2:$B$235,2,0),1,(Table1[[#This Row],[CRD]]-Table1[[#This Row],[PO APPR DATE]])>VLOOKUP(Table1[[#This Row],[Supplier ]],SupplierLeadTimeMaster!$A$2:$B$235,2,0),1-ABS(Table1[[#This Row],[CRD]]-Table1[[#This Row],[PO APPR DATE]])/VLOOKUP(Table1[[#This Row],[Supplier ]],SupplierLeadTimeMaster!$A$2:$B$235,2,0)),"")} -> 0 | BC6: =IFERROR(IF(AND(Table1[[#This Row],[ETD]]>0,Table1[[#This Row],[No of Days ISS Cont Booking LT]]>0),IF((Table1[[#This Row],[ETD]]-Table1[[#This Row],[CRD]])<=7,1,1-ABS(Table1[[#This Row],[ETD]]-Table1[[#This Row],[CRD]])/7),0),"") -> 0 | BD6: {=_xlfn.IFS(Table1[[#This Row],[DEL]]="",0,Table1[[#This Row],[ORG COUNTRY]]="",0,ISBLANK(Table1[[#This Row],[ETD]]),0,Table1[[#This Row],[ETA]]="",0,Table1[[#This Row],[ETA]]-Table1[[#This Row],[ETD]]<=VLOOKUP(Table1[[#This Row],[ORG COUNTRY]],CountryTransitTimeMaster!$B$2:$C$44,2,FALSE),1,Table1[[#This Row],[ETA]]-Table1[[#This Row],[ETD]]>VLOOKUP(Table1[[#This Row],[ORG COUNTRY]],CountryTransitTimeMaster!$B$2:$C$44,2,FALSE),1-ABS(Table1[[#This Row],[ETA]]-Table1[[#This Row],[ETD]])/VLOOKUP(Table1[[#This Row],[ORG COUNTRY]],CountryTransitTimeMaster!$B$2:$C$44,2,FALSE))} -> 0 | BE6: {=_xlfn.IFS(Table1[[#This Row],[DEL]]="",0,ISBLANK(Table1[[#This Row],[DEL]]),0,Table1[[#This Row],[DEL]]-Table1[[#This Row],[ETA]]<=3,1,(Table1[[#This Row],[DEL]]-Table1[[#This Row],[ETA]])>3,1-ABS(Table1[[#This Row],[DEL]]-Table1[[#This Row],[ETA]])/3)} -> 0 | BF6: =IFERROR(IF(Table1[[#This Row],[E2E Total LT]]>0,1-ABS(Table1[[#This Row],[E2E Total LT]]-Table1[[#This Row],[No of Days Total Comm LT (as per contract)]])/Table1[[#This Row],[No of Days Total Comm LT (as per contract)]],0),"") -> 0 | BG6: {=_xlfn.IFS(Table1[[#This Row],[DEL]]="",0,Table1[[#This Row],[STATUS]]="Cancelled",0,Table1[[#This Row],[ORG COUNTRY]]="",0,ISNONTEXT(Table1[[#This Row],[DEL]]),SUM(VLOOKUP(Table1[[#This Row],[Supplier ]],SupplierLeadTimeMaster!$A$2:$B$235,2,FALSE),VLOOKUP(Table1[[#This Row],[ORG COUNTRY]],CountryTransitTimeMaster!$B$2:$C$44,2,FALSE),7,3,5))} -> 0 | BH6: =IFERROR(IF(SUM(Table1[[#This Row],[No of Days Order Placement LT]],Table1[[#This Row],[No of Days Supplier Production Lead Time]],Table1[[#This Row],[No of Days Custom Clearance LT]],Table1[[#This Row],[No of Days ISS Cont Booking LT]],Table1[[#This Row],[No of Days Transit LT]])>500,0,SUM(Table1[[#This Row],[No of Days Order Placement LT]],Table1[[#This Row],[No of Days Supplier Production Lead Time]],Table1[[#This Row],[No of Days Custom Clearance LT]],Table1[[#This Row],[No of Days ISS Cont Booking LT]],Table1[[#This Row],[No of Days Transit LT]])),0) -> 0 | BI6: {=IFERROR(_xlfn.IFS((Table1[[#This Row],[No of Days Supplier Production Lead Time]])=" "," ",Table1[[#This Row],[Actual Lead (PO to Date)]]-Table1[[#This Row],[No of Days Total Comm LT (as per contract)]]<=15,"Healthy",Table1[[#This Row],[Actual Lead (PO to Date)]]-Table1[[#This Row],[No of Days Total Comm LT (as per contract)]]<=30,"Minor",Table1[[#This Row],[Actual Lead (PO to Date)]]-Table1[[#This Row],[No of Days Total Comm LT (as per contract)]]<=45,"Moderate",Table1[[#This Row],[Actual Lead (PO to Date)]]-Table1[[#This Row],[No of Days Total Comm LT (as per contract)]]<=60,"Major",Table1[[#This Row],[Actual Lead (PO to Date)]]-Table1[[#This Row],[No of Days Total Comm LT (as per contract)]]>60,"Severe",ISBLANK(Table1[[#This Row],[DEL]])," ",ISBLANK(Table1[[#This Row],[ETA]])," ",ISBLANK(Table1[[#This Row],[ETD]])," ",ISBLANK(Table1[[#This Row],[PR APPR DATE]])," ",ISBLANK(Table1[[#This Row],[Actual Lead (PO to Date)]])," ",ISBLANK(Table1[[#This Row],[No of Days Total Comm LT (as per contract)]])," ")," ")} -> Healthy | BJ6: {=IFERROR(_xlfn.IFS(Table1[[#This Row],[HEALTH CHECK]]=" ","",Table1[[#This Row],[HEALTH CHECK]]="Healthy"," ",Table1[[#This Row],[ON TIME ORDER PLACEMENT PERF %]]<100%,"PR to PO Delay",Table1[[#This Row],[Supplier committed product readiness performance % ]]<100%,"Product Readiness Delay",Table1[[#This Row],[ISS container booking performance %]]<100%,"Booking Delay",Table1[[#This Row],[ISS Transit Lead Time Perf %]]<100%,"Trans Shipment Delay",Table1[[#This Row],[ISS custom clearance Perf % ]]<100%,"Custom Clearance Delay")," ")} | BK6: {=_xlfn.IFS(ISBLANK(Table1[[#This Row],[PR APPR DATE]]),0,ISBLANK(Table1[[#This Row],[PO APPR DATE]]),0,ISNONTEXT(Table1[[#This Row],[PO APPR DATE]]),Table1[[#This Row],[PO APPR DATE]]-Table1[[#This Row],[PR APPR DATE]])} -> 0 | BL6: {=_xlfn.IFS((Table1[[#This Row],[DEL]])="",0,ISBLANK(Table1[[#This Row],[CRD]]),0,ISBLANK(Table1[[#This Row],[PO APPR DATE]]),0,ISNONTEXT(Table1[[#This Row],[PO APPR DATE]]),Table1[[#This Row],[CRD]]-Table1[[#This Row],[PO APPR DATE]])} -> 0 | BM6: =IFERROR(IF(Table1[[#This Row],[DEL]]>0,Table1[[#This Row],[DEL]]-Table1[[#This Row],[ETA]],0),0) -> 0 | BN6: =IFERROR(IF(Table1[[#This Row],[ETD]]>0,(Table1[[#This Row],[ETD]]-Table1[[#This Row],[CRD]]),0),"") -> 0 | BO6: =IFERROR(IF(Table1[[#This Row],[ETA]]>0,(Table1[[#This Row],[ETA]]-Table1[[#This Row],[ETD]]),0),0) -> 0 | BP6: {=_xlfn.IFS(Table1[[#This Row],[DEL]]="",0,Table1[[#This Row],[DEL]]="",0,ISBLANK(Table1[[#This Row],[PR APPR DATE]]),0,ISBLANK(Table1[[#This Row],[DEL]]),0,ISNONTEXT(Table1[[#This Row],[PR APPR DATE]]),Table1[[#This Row],[DEL]]-Table1[[#This Row],[PR APPR DATE]],Table1[[#This Row],[DEL]]="",0)} -> 0 | BQ6: =Table1[[#This Row],[ORG CHGS (AED)]]/3.673 -> 0 | BR6: =Table1[[#This Row],[FRT CHGS (AED)]]/3.673 -> 0 | BS6: =Table1[[#This Row],[DEST CHGS (AED)]]/3.673 -> 0 | BY6: =SUM(Table1[[#This Row],[ORG CHGS (AED)]],Table1[[#This Row],[FRT CHGS (AED)]],Table1[[#This Row],[DEST CHGS (AED)]]) -> 0 | BZ6: =SUM(Table1[[#This Row],[P2P VALUE]]+Table1[[#This Row],[Ancillary Charges (AED)]]) -> 0 | CD6: =IF(ISBLANK(Table1[[#This Row],[PR DATE]]),"Pending","Logged") -> Pending | CF6: =IF(ISBLANK(Table1[[#This Row],[SPO '#]]),"Pending","Received") -> Pending | CJ6: {=_xlfn.IFS(ISTEXT(Table1[[#This Row],[Invoice '#]]),"Billed",Table1[[#This Row],[PO STATUS]]="Received","Pending",Table1[[#This Row],[PO STATUS]]="Pending","Pending")} -> Pending | CM6: =IF(ISBLANK(Table1[[#This Row],[GRN]]),"Pending","Complete") -> Pending | CU6: =IF(Table1[[#This Row],[DEL]]="","",Table1[[#This Row],[REVISED ETD]]-Table1[[#This Row],[ETD]]) | CV6: =IF(Table1[[#This Row],[DEL]]="","",Table1[[#This Row],[REVISED ETA]]-Table1[[#This Row],[ETA]]) | CW6: =IF(Table1[[#This Row],[DEL]]="","",Table1[[#This Row],[ETA]]-Table1[[#This Row],[PO NEED BY DATE]]) | CX6: =Table1[[#This Row],[Invoice (AED)]]/3.673 -> 0 | CY6: {=_xlfn.IFS(Table1[[#This Row],[STATUS]]="Cancelled",,Table1[[#This Row],[STATUS]]="Pending",,Table1[[#This Row],[STATUS]]="Not Due",,ISNONTEXT(Table1[[#This Row],[CRD]]),Table1[[#This Row],[CRD]]-Table1[[#This Row],[PO NEED BY DATE]])} -> 0 | CZ6: =IF(Table1[[#This Row],[CRD]]<>"", Table1[[#This Row],[CRD]]-Table1[[#This Row],[PO CREATION DATE]], 0) -> 0 | DA6: =IF(Table1[[#This Row],[REVISED ETD]]<>"", Table1[[#This Row],[REVISED ETD]]-Table1[[#This Row],[CRD]], Table1[[#This Row],[ETD]]-Table1[[#This Row],[CRD]]) -> 0 | DB6: =IF(AND(Table1[[#This Row],[REVISED ETD]]<>"", Table1[[#This Row],[REVISED ETA]]<>""), Table1[[#This Row],[REVISED ETA]]-Table1[[#This Row],[REVISED ETD]], IF(AND(Table1[[#This Row],[REVISED ETA]]<>"", Table1[[#This Row],[REVISED ETD]]=""), Table1[[#This Row],[REVISED ETA]]-Table1[[#This Row],[ETD]], IF(AND(Table1[[#This Row],[REVISED ETA]]="", Table1[[#This Row],[REVISED ETD]]<>""), Table1[[#This Row],[ETA]]-Table1[[#This Row],[REVISED ETD]], IF(AND(Table1[[#This Row],[REVISED ETA]]="", Table1[[#This Row],[REVISED ETD]]=""), Table1[[#This Row],[ETA]]-Table1[[#This Row],[ETD]], "") ) ) ) -> 0 | DC6: =IF(Table1[[#This Row],[REVISED ETA]]<>"", Table1[[#This Row],[DEL]]-Table1[[#This Row],[REVISED ETA]], Table1[[#This Row],[DEL]]-Table1[[#This Row],[ETA]]) -> 0 | DD6: {=_xlfn.IFS(Table1[[#This Row],[STATUS]]="Cancelled",,Table1[[#This Row],[STATUS]]="Pending",,Table1[[#This Row],[STATUS]]="Not Due",,ISNONTEXT(Table1[[#This Row],[ETD]]),Table1[[#This Row],[ETA]]-Table1[[#This Row],[PO NEED BY DATE]])} -> 0 | DE6: =Table1[[#This Row],[PO NEED BY DATE]]-Table1[[#This Row],[DEL]] -> 46057 | DF6: =SUM(Table1[[#This Row],[CRD TO ETD]],Table1[[#This Row],[ETD TO ETA]],Table1[[#This Row],[ETA TO DEL]],Table1[[#This Row],[NBD TO ETA]],Table1[[#This Row],[NBD TO DEL]]) -> 46057
C7: STEP SOURCING TRADING L.L.C | D7: 422016887-19 | F7: fc coaster | G7: FC Cotton Coaster | AA7: 45945 | AB7: 45945 | AC7: 45945 | AD7: 45947 | AE7: 46042 | AO7: Pending | AQ7: 480000 | BA7: =IF(Table1[[#This Row],[PO APPR DATE]]>0,IF(Table1[[#This Row],[PO APPR DATE]]-Table1[[#This Row],[PR APPR DATE]]<=5,1,1-ABS(Table1[[#This Row],[PO APPR DATE]]-Table1[[#This Row],[PR APPR DATE]])/5),0) -> 1 | BB7: {=IFERROR(_xlfn.IFS(ISBLANK(Table1[[#This Row],[PO APPR DATE]]),0,Table1[[#This Row],[CRD]]="",0,Table1[[#This Row],[CRD]]-Table1[[#This Row],[PO APPR DATE]]<=VLOOKUP(Table1[[#This Row],[Supplier ]],SupplierLeadTimeMaster!$A$2:$B$235,2,0),1,(Table1[[#This Row],[CRD]]-Table1[[#This Row],[PO APPR DATE]])>VLOOKUP(Table1[[#This Row],[Supplier ]],SupplierLeadTimeMaster!$A$2:$B$235,2,0),1-ABS(Table1[[#This Row],[CRD]]-Table1[[#This Row],[PO APPR DATE]])/VLOOKUP(Table1[[#This Row],[Supplier ]],SupplierLeadTimeMaster!$A$2:$B$235,2,0)),"")} -> 0 | BC7: =IFERROR(IF(AND(Table1[[#This Row],[ETD]]>0,Table1[[#This Row],[No of Days ISS Cont Booking LT]]>0),IF((Table1[[#This Row],[ETD]]-Table1[[#This Row],[CRD]])<=7,1,1-ABS(Table1[[#This Row],[ETD]]-Table1[[#This Row],[CRD]])/7),0),"") -> 0 | BD7: {=_xlfn.IFS(Table1[[#This Row],[DEL]]="",0,Table1[[#This Row],[ORG COUNTRY]]="",0,ISBLANK(Table1[[#This Row],[ETD]]),0,Table1[[#This Row],[ETA]]="",0,Table1[[#This Row],[ETA]]-Table1[[#This Row],[ETD]]<=VLOOKUP(Table1[[#This Row],[ORG COUNTRY]],CountryTransitTimeMaster!$B$2:$C$44,2,FALSE),1,Table1[[#This Row],[ETA]]-Table1[[#This Row],[ETD]]>VLOOKUP(Table1[[#This Row],[ORG COUNTRY]],CountryTransitTimeMaster!$B$2:$C$44,2,FALSE),1-ABS(Table1[[#This Row],[ETA]]-Table1[[#This Row],[ETD]])/VLOOKUP(Table1[[#This Row],[ORG COUNTRY]],CountryTransitTimeMaster!$B$2:$C$44,2,FALSE))} -> 0 | BE7: {=_xlfn.IFS(Table1[[#This Row],[DEL]]="",0,ISBLANK(Table1[[#This Row],[DEL]]),0,Table1[[#This Row],[DEL]]-Table1[[#This Row],[ETA]]<=3,1,(Table1[[#This Row],[DEL]]-Table1[[#This Row],[ETA]])>3,1-ABS(Table1[[#This Row],[DEL]]-Table1[[#This Row],[ETA]])/3)} -> 0 | BF7: =IFERROR(IF(Table1[[#This Row],[E2E Total LT]]>0,1-ABS(Table1[[#This Row],[E2E Total LT]]-Table1[[#This Row],[No of Days Total Comm LT (as per contract)]])/Table1[[#This Row],[No of Days Total Comm LT (as per contract)]],0),"") -> 0 | BG7: {=_xlfn.IFS(Table1[[#This Row],[DEL]]="",0,Table1[[#This Row],[STATUS]]="Cancelled",0,Table1[[#This Row],[ORG COUNTRY]]="",0,ISNONTEXT(Table1[[#This Row],[DEL]]),SUM(VLOOKUP(Table1[[#This Row],[Supplier ]],SupplierLeadTimeMaster!$A$2:$B$235,2,FALSE),VLOOKUP(Table1[[#This Row],[ORG COUNTRY]],CountryTransitTimeMaster!$B$2:$C$44,2,FALSE),7,3,5))} -> 0 | BH7: =IFERROR(IF(SUM(Table1[[#This Row],[No of Days Order Placement LT]],Table1[[#This Row],[No of Days Supplier Production Lead Time]],Table1[[#This Row],[No of Days Custom Clearance LT]],Table1[[#This Row],[No of Days ISS Cont Booking LT]],Table1[[#This Row],[No of Days Transit LT]])>500,0,SUM(Table1[[#This Row],[No of Days Order Placement LT]],Table1[[#This Row],[No of Days Supplier Production Lead Time]],Table1[[#This Row],[No of Days Custom Clearance LT]],Table1[[#This Row],[No of Days ISS Cont Booking LT]],Table1[[#This Row],[No of Days Transit LT]])),0) -> 0 | BI7: {=IFERROR(_xlfn.IFS((Table1[[#This Row],[No of Days Supplier Production Lead Time]])=" "," ",Table1[[#This Row],[Actual Lead (PO to Date)]]-Table1[[#This Row],[No of Days Total Comm LT (as per contract)]]<=15,"Healthy",Table1[[#This Row],[Actual Lead (PO to Date)]]-Table1[[#This Row],[No of Days Total Comm LT (as per contract)]]<=30,"Minor",Table1[[#This Row],[Actual Lead (PO to Date)]]-Table1[[#This Row],[No of Days Total Comm LT (as per contract)]]<=45,"Moderate",Table1[[#This Row],[Actual Lead (PO to Date)]]-Table1[[#This Row],[No of Days Total Comm LT (as per contract)]]<=60,"Major",Table1[[#This Row],[Actual Lead (PO to Date)]]-Table1[[#This Row],[No of Days Total Comm LT (as per contract)]]>60,"Severe",ISBLANK(Table1[[#This Row],[DEL]])," ",ISBLANK(Table1[[#This Row],[ETA]])," ",ISBLANK(Table1[[#This Row],[ETD]])," ",ISBLANK(Table1[[#This Row],[PR APPR DATE]])," ",ISBLANK(Table1[[#This Row],[Actual Lead (PO to Date)]])," ",ISBLANK(Table1[[#This Row],[No of Days Total Comm LT (as per contract)]])," ")," ")} -> Healthy | BJ7: {=IFERROR(_xlfn.IFS(Table1[[#This Row],[HEALTH CHECK]]=" ","",Table1[[#This Row],[HEALTH CHECK]]="Healthy"," ",Table1[[#This Row],[ON TIME ORDER PLACEMENT PERF %]]<100%,"PR to PO Delay",Table1[[#This Row],[Supplier committed product readiness performance % ]]<100%,"Product Readiness Delay",Table1[[#This Row],[ISS container booking performance %]]<100%,"Booking Delay",Table1[[#This Row],[ISS Transit Lead Time Perf %]]<100%,"Trans Shipment Delay",Table1[[#This Row],[ISS custom clearance Perf % ]]<100%,"Custom Clearance Delay")," ")} | BK7: {=_xlfn.IFS(ISBLANK(Table1[[#This Row],[PR APPR DATE]]),0,ISBLANK(Table1[[#This Row],[PO APPR DATE]]),0,ISNONTEXT(Table1[[#This Row],[PO APPR DATE]]),Table1[[#This Row],[PO APPR DATE]]-Table1[[#This Row],[PR APPR DATE]])} -> 0 | BL7: {=_xlfn.IFS((Table1[[#This Row],[DEL]])="",0,ISBLANK(Table1[[#This Row],[CRD]]),0,ISBLANK(Table1[[#This Row],[PO APPR DATE]]),0,ISNONTEXT(Table1[[#This Row],[PO APPR DATE]]),Table1[[#This Row],[CRD]]-Table1[[#This Row],[PO APPR DATE]])} -> 0 | BM7: =IFERROR(IF(Table1[[#This Row],[DEL]]>0,Table1[[#This Row],[DEL]]-Table1[[#This Row],[ETA]],0),0) -> 0 | BN7: =IFERROR(IF(Table1[[#This Row],[ETD]]>0,(Table1[[#This Row],[ETD]]-Table1[[#This Row],[CRD]]),0),"") -> 0 | BO7: =IFERROR(IF(Table1[[#This Row],[ETA]]>0,(Table1[[#This Row],[ETA]]-Table1[[#This Row],[ETD]]),0),0) -> 0 | BP7: {=_xlfn.IFS(Table1[[#This Row],[DEL]]="",0,Table1[[#This Row],[DEL]]="",0,ISBLANK(Table1[[#This Row],[PR APPR DATE]]),0,ISBLANK(Table1[[#This Row],[DEL]]),0,ISNONTEXT(Table1[[#This Row],[PR APPR DATE]]),Table1[[#This Row],[DEL]]-Table1[[#This Row],[PR APPR DATE]],Table1[[#This Row],[DEL]]="",0)} -> 0 | BQ7: =Table1[[#This Row],[ORG CHGS (AED)]]/3.673 -> 0 | BR7: =Table1[[#This Row],[FRT CHGS (AED)]]/3.673 -> 0 | BS7: =Table1[[#This Row],[DEST CHGS (AED)]]/3.673 -> 0 | BY7: =SUM(Table1[[#This Row],[ORG CHGS (AED)]],Table1[[#This Row],[FRT CHGS (AED)]],Table1[[#This Row],[DEST CHGS (AED)]]) -> 0 | BZ7: =SUM(Table1[[#This Row],[P2P VALUE]]+Table1[[#This Row],[Ancillary Charges (AED)]]) -> 0 | CD7: =IF(ISBLANK(Table1[[#This Row],[PR DATE]]),"Pending","Logged") -> Pending | CF7: =IF(ISBLANK(Table1[[#This Row],[SPO '#]]),"Pending","Received") -> Pending | CJ7: {=_xlfn.IFS(ISTEXT(Table1[[#This Row],[Invoice '#]]),"Billed",Table1[[#This Row],[PO STATUS]]="Received","Pending",Table1[[#This Row],[PO STATUS]]="Pending","Pending")} -> Pending | CM7: =IF(ISBLANK(Table1[[#This Row],[GRN]]),"Pending","Complete") -> Pending | CU7: =IF(Table1[[#This Row],[DEL]]="","",Table1[[#This Row],[REVISED ETD]]-Table1[[#This Row],[ETD]]) | CV7: =IF(Table1[[#This Row],[DEL]]="","",Table1[[#This Row],[REVISED ETA]]-Table1[[#This Row],[ETA]]) | CW7: =IF(Table1[[#This Row],[DEL]]="","",Table1[[#This Row],[ETA]]-Table1[[#This Row],[PO NEED BY DATE]]) | CX7: =Table1[[#This Row],[Invoice (AED)]]/3.673 -> 0 | CY7: {=_xlfn.IFS(Table1[[#This Row],[STATUS]]="Cancelled",,Table1[[#This Row],[STATUS]]="Pending",,Table1[[#This Row],[STATUS]]="Not Due",,ISNONTEXT(Table1[[#This Row],[CRD]]),Table1[[#This Row],[CRD]]-Table1[[#This Row],[PO NEED BY DATE]])} -> 0 | CZ7: =IF(Table1[[#This Row],[CRD]]<>"", Table1[[#This Row],[CRD]]-Table1[[#This Row],[PO CREATION DATE]], 0) -> 0 | DA7: =IF(Table1[[#This Row],[REVISED ETD]]<>"", Table1[[#This Row],[REVISED ETD]]-Table1[[#This Row],[CRD]], Table1[[#This Row],[ETD]]-Table1[[#This Row],[CRD]]) -> 0 | DB7: =IF(AND(Table1[[#This Row],[REVISED ETD]]<>"", Table1[[#This Row],[REVISED ETA]]<>""), Table1[[#This Row],[REVISED ETA]]-Table1[[#This Row],[REVISED ETD]], IF(AND(Table1[[#This Row],[REVISED ETA]]<>"", Table1[[#This Row],[REVISED ETD]]=""), Table1[[#This Row],[REVISED ETA]]-Table1[[#This Row],[ETD]], IF(AND(Table1[[#This Row],[REVISED ETA]]="", Table1[[#This Row],[REVISED ETD]]<>""), Table1[[#This Row],[ETA]]-Table1[[#This Row],[REVISED ETD]], IF(AND(Table1[[#This Row],[REVISED ETA]]="", Table1[[#This Row],[REVISED ETD]]=""), Table1[[#This Row],[ETA]]-Table1[[#This Row],[ETD]], "") ) ) ) -> 0 | DC7: =IF(Table1[[#This Row],[REVISED ETA]]<>"", Table1[[#This Row],[DEL]]-Table1[[#This Row],[REVISED ETA]], Table1[[#This Row],[DEL]]-Table1[[#This Row],[ETA]]) -> 0 | DD7: {=_xlfn.IFS(Table1[[#This Row],[STATUS]]="Cancelled",,Table1[[#This Row],[STATUS]]="Pending",,Table1[[#This Row],[STATUS]]="Not Due",,ISNONTEXT(Table1[[#This Row],[ETD]]),Table1[[#This Row],[ETA]]-Table1[[#This Row],[PO NEED BY DATE]])} -> 0 | DE7: =Table1[[#This Row],[PO NEED BY DATE]]-Table1[[#This Row],[DEL]] -> 46042 | DF7: =SUM(Table1[[#This Row],[CRD TO ETD]],Table1[[#This Row],[ETD TO ETA]],Table1[[#This Row],[ETA TO DEL]],Table1[[#This Row],[NBD TO ETA]],Table1[[#This Row],[NBD TO DEL]]) -> 46042
